Traceback (most recent call last):
  File "bug.py", line 8, in <module>
    GPIO.setup("P8_38", GPIO.IN)
ValueError: Set gpio mode failed, missing file or invalid permissions.

